<?xml version="1.0" encoding="utf-8"?><testsuites><testsuite name="pytest" errors="3" failures="0" skipped="0" tests="3" time="8.636" timestamp="2025-07-25T00:06:33.513057" hostname="GoodgooddeMacBook-Air.local"><testcase classname="" name="tests.test_analysis" time="0.000"><error message="collection failure">ImportError while importing test module '/Users/goodgoodstudy/Desktop/aicode/mrna2/tests/test_analysis.py'.
Hint: make sure your test modules/packages have valid Python names.
Traceback:
/opt/anaconda3/lib/python3.12/site-packages/_pytest/python.py:617: in _importtestmodule
    mod = import_path(self.path, mode=importmode, root=self.config.rootpath)
/opt/anaconda3/lib/python3.12/site-packages/_pytest/pathlib.py:567: in import_path
    importlib.import_module(module_name)
/opt/anaconda3/lib/python3.12/importlib/__init__.py:90: in import_module
    return _bootstrap._gcd_import(name[level:], package, level)
&lt;frozen importlib._bootstrap&gt;:1387: in _gcd_import
    ???
&lt;frozen importlib._bootstrap&gt;:1360: in _find_and_load
    ???
&lt;frozen importlib._bootstrap&gt;:1331: in _find_and_load_unlocked
    ???
&lt;frozen importlib._bootstrap&gt;:935: in _load_unlocked
    ???
/opt/anaconda3/lib/python3.12/site-packages/_pytest/assertion/rewrite.py:186: in exec_module
    exec(co, module.__dict__)
tests/test_analysis.py:19: in &lt;module&gt;
    from analysis.stage1_multidimensional import MultidimensionalAnalyzer
E   ImportError: cannot import name 'MultidimensionalAnalyzer' from 'analysis.stage1_multidimensional' (/Users/goodgoodstudy/Desktop/aicode/mrna2/src/analysis/stage1_multidimensional.py)</error></testcase><testcase classname="" name="tests.test_api_comprehensive" time="0.000"><error message="collection failure">tests/test_api_comprehensive.py:21: in &lt;module&gt;
    from src.api.main import app
src/api/main.py:154: in &lt;module&gt;
    from src.api.auth_endpoints import router as auth_router
src/api/auth_endpoints.py:13: in &lt;module&gt;
    from src.database.models import User, SessionLocal
src/database/models.py:49: in &lt;module&gt;
    class Dataset(Base):
/opt/anaconda3/lib/python3.12/site-packages/sqlalchemy/orm/decl_api.py:196: in __init__
    _as_declarative(reg, cls, dict_)
/opt/anaconda3/lib/python3.12/site-packages/sqlalchemy/orm/decl_base.py:244: in _as_declarative
    return _MapperConfig.setup_mapping(registry, cls, dict_, None, {})
/opt/anaconda3/lib/python3.12/site-packages/sqlalchemy/orm/decl_base.py:325: in setup_mapping
    return _ClassScanMapperConfig(
/opt/anaconda3/lib/python3.12/site-packages/sqlalchemy/orm/decl_base.py:572: in __init__
    self._extract_mappable_attributes()
/opt/anaconda3/lib/python3.12/site-packages/sqlalchemy/orm/decl_base.py:1523: in _extract_mappable_attributes
    raise exc.InvalidRequestError(
E   sqlalchemy.exc.InvalidRequestError: Attribute name 'metadata' is reserved when using the Declarative API.</error></testcase><testcase classname="" name="tests.test_integrated_analysis" time="0.000"><error message="collection failure">ImportError while importing test module '/Users/goodgoodstudy/Desktop/aicode/mrna2/tests/test_integrated_analysis.py'.
Hint: make sure your test modules/packages have valid Python names.
Traceback:
/opt/anaconda3/lib/python3.12/site-packages/_pytest/python.py:617: in _importtestmodule
    mod = import_path(self.path, mode=importmode, root=self.config.rootpath)
/opt/anaconda3/lib/python3.12/site-packages/_pytest/pathlib.py:567: in import_path
    importlib.import_module(module_name)
/opt/anaconda3/lib/python3.12/importlib/__init__.py:90: in import_module
    return _bootstrap._gcd_import(name[level:], package, level)
&lt;frozen importlib._bootstrap&gt;:1387: in _gcd_import
    ???
&lt;frozen importlib._bootstrap&gt;:1360: in _find_and_load
    ???
&lt;frozen importlib._bootstrap&gt;:1331: in _find_and_load_unlocked
    ???
&lt;frozen importlib._bootstrap&gt;:935: in _load_unlocked
    ???
/opt/anaconda3/lib/python3.12/site-packages/_pytest/assertion/rewrite.py:186: in exec_module
    exec(co, module.__dict__)
tests/test_integrated_analysis.py:13: in &lt;module&gt;
    from src.analysis.integrated_analysis import IntegratedAnalysisPipeline
src/analysis/integrated_analysis.py:17: in &lt;module&gt;
    from analysis.stage1_multidimensional import Stage1Analyzer
E   ImportError: cannot import name 'Stage1Analyzer' from 'analysis.stage1_multidimensional' (/Users/goodgoodstudy/Desktop/aicode/mrna2/src/analysis/stage1_multidimensional.py)</error></testcase></testsuite></testsuites>